Workbook

Sheet README
A1: Tomo ICSE Concept-Block Map — v1 (working draft)
A3: Purpose
A4: Every subject, Grades 1-12, broken into units and concept blocks with delivery mode, mastery proof, progression logic and path-lock criteria. This sheet is the 'track' on which per-subject student progression runs (see project doc: Doc 3 — Scholar Path & Subject-Level Progression). It is the India-native equivalent of Alpha School's mastery knowledge graph (Doc 1).
A6: How to read a row
A7: One row = one unit. Concept_Blocks lists the granular nodes a child masters one by one inside that unit. A child's 'working level' in a subject = the furthest unit proven via the Mastery_Proof column (always AI-free). Unlocks shows what passing opens; Path_Lock shows what holds progression; Scholar_Depth is the extension lane for advanced students (depth gates velocity — see Doc 3 §3.4).
A9: Delivery codes
A10: T = teacher-first · A = AI-doorway-first (AI introduces the concept through the child's interest doorway, then teacher teaches the actual room) · M = manipulatives/physical · R = adaptive practice ladder · L = lab/experiment · N = nature/outdoor · P = project · O = oral/discussion/performance · U = unplugged (computer science without screens) · C = computer lab
A11: Design rule: Grades 1-3 are M/T/O-heavy (low-screen policy per Blueprint §17.1). AI-doorway-first delivery begins Grade 4-5 and is standard from middle school.
A13: Sourcing and confidence
A14: Grades 9-10: unit names follow the official ICSE syllabus (verified against CISCE syllabus documents, 2026-27 exam-year where available; re-verify against the current CISCE PDF each year — prescribed literature texts rotate). Grades 11-12: ISC Science-stream syllabus (Physics, Chemistry, Biology, Mathematics, Computer Science, English). Grades 1-8: CISCE prescribes a curriculum framework but pacing/pedagogy below Class 9 is a school decision in practice — these rows are school-defined, NCF-aligned, and deliberately sequenced to land exactly at the ICSE Class 9 entry points.
A16: Scope decisions taken in this draft (flagged, reversible)
A17: 1. ISC (11-12) mapped for the Science stream only; Commerce/Humanities to be added once the school's stream offering is decided.
... A25: Version: v1 — July 15, 2026 · Built by Founders Office · Companion docs: Doc 1 (Alpha deep-dive), Doc 3 (Scholar path / progression)

Sheet Dashboard
A1: Dashboard — coverage by grade and subject
A2: All figures are live formulas over the subject tabs (COUNTIF / SUMIF). Zero = subject not offered at that grade.
A4: Units mapped
A5: Grade | B5: Mathematics | C5: English | D5: Hindi/2nd language | E5: Science 1-8 | F5: PCB 9-12 | G5: Social Studies | H5: Computer | I5: Total
A6: 1 | B6: =COUNTIF(Mathematics!$A:$A,$A6) -> 6 | C6: =COUNTIF(English!$A:$A,$A6) -> 6 | D6: =COUNTIF(Hindi!$A:$A,$A6) -> 6 | E6: =COUNTIF('Science 1-8'!$A:$A,$A6) -> 6 | F6: =COUNTIF('PCB 9-12'!$A:$A,$A6) -> 0 | G6: =COUNTIF('Social Studies'!$A:$A,$A6) -> 5 | H6: =COUNTIF(Computer!$A:$A,$A6) -> 5 | I6: =SUM(B6:H6) -> 34
A7: 2 | B7: =COUNTIF(Mathematics!$A:$A,$A7) -> 6 | C7: =COUNTIF(English!$A:$A,$A7) -> 6 | D7: =COUNTIF(Hindi!$A:$A,$A7) -> 6 | E7: =COUNTIF('Science 1-8'!$A:$A,$A7) -> 6 | F7: =COUNTIF('PCB 9-12'!$A:$A,$A7) -> 0 | G7: =COUNTIF('Social Studies'!$A:$A,$A7) -> 6 | H7: =COUNTIF(Computer!$A:$A,$A7) -> 5 | I7: =SUM(B7:H7) -> 35
A8: 3 | B8: =COUNTIF(Mathematics!$A:$A,$A8) -> 7 | C8: =COUNTIF(English!$A:$A,$A8) -> 7 | D8: =COUNTIF(Hindi!$A:$A,$A8) -> 6 | E8: =COUNTIF('Science 1-8'!$A:$A,$A8) -> 8 | F8: =COUNTIF('PCB 9-12'!$A:$A,$A8) -> 0 | G8: =COUNTIF('Social Studies'!$A:$A,$A8) -> 7 | H8: =COUNTIF(Computer!$A:$A,$A8) -> 6 | I8: =SUM(B8:H8) -> 41
A9: 4 | B9: =COUNTIF(Mathematics!$A:$A,$A9) -> 8 | C9: =COUNTIF(English!$A:$A,$A9) -> 7 | D9: =COUNTIF(Hindi!$A:$A,$A9) -> 6 | E9: =COUNTIF('Science 1-8'!$A:$A,$A9) -> 9 | F9: =COUNTIF('PCB 9-12'!$A:$A,$A9) -> 0 | G9: =COUNTIF('Social Studies'!$A:$A,$A9) -> 7 | H9: =COUNTIF(Computer!$A:$A,$A9) -> 6 | I9: =SUM(B9:H9) -> 43
A10: 5 | B10: =COUNTIF(Mathematics!$A:$A,$A10) -> 8 | C10: =COUNTIF(English!$A:$A,$A10) -> 8 | D10: =COUNTIF(Hindi!$A:$A,$A10) -> 6 | E10: =COUNTIF('Science 1-8'!$A:$A,$A10) -> 9 | F10: =COUNTIF('PCB 9-12'!$A:$A,$A10) -> 0 | G10: =COUNTIF('Social Studies'!$A:$A,$A10) -> 7 | H10: =COUNTIF(Computer!$A:$A,$A10) -> 6 | I10: =SUM(B10:H10) -> 44
A11: 6 | B11: =COUNTIF(Mathematics!$A:$A,$A11) -> 9 | C11: =COUNTIF(English!$A:$A,$A11) -> 8 | D11: =COUNTIF(Hindi!$A:$A,$A11) -> 7 | E11: =COUNTIF('Science 1-8'!$A:$A,$A11) -> 8 | F11: =COUNTIF('PCB 9-12'!$A:$A,$A11) -> 0 | G11: =COUNTIF('Social Studies'!$A:$A,$A11) -> 9 | H11: =COUNTIF(Computer!$A:$A,$A11) -> 6 | I11: =SUM(B11:H11) -> 47
A12: 7 | B12: =COUNTIF(Mathematics!$A:$A,$A12) -> 9 | C12: =COUNTIF(English!$A:$A,$A12) -> 8 | D12: =COUNTIF(Hindi!$A:$A,$A12) -> 7 | E12: =COUNTIF('Science 1-8'!$A:$A,$A12) -> 8 | F12: =COUNTIF('PCB 9-12'!$A:$A,$A12) -> 0 | G12: =COUNTIF('Social Studies'!$A:$A,$A12) -> 9 | H12: =COUNTIF(Computer!$A:$A,$A12) -> 6 | I12: =SUM(B12:H12) -> 47
A13: 8 | B13: =COUNTIF(Mathematics!$A:$A,$A13) -> 10 | C13: =COUNTIF(English!$A:$A,$A13) -> 8 | D13: =COUNTIF(Hindi!$A:$A,$A13) -> 7 | E13: =COUNTIF('Science 1-8'!$A:$A,$A13) -> 9 | F13: =COUNTIF('PCB 9-12'!$A:$A,$A13) -> 0 | G13: =COUNTIF('Social Studies'!$A:$A,$A13) -> 10 | H13: =COUNTIF(Computer!$A:$A,$A13) -> 6 | I13: =SUM(B13:H13) -> 50
A14: 9 | B14: =COUNTIF(Mathematics!$A:$A,$A14) -> 10 | C14: =COUNTIF(English!$A:$A,$A14) -> 9 | D14: =COUNTIF(Hindi!$A:$A,$A14) -> 6 | E14: =COUNTIF('Science 1-8'!$A:$A,$A14) -> 0 | F14: =COUNTIF('PCB 9-12'!$A:$A,$A14) -> 24 | G14: =COUNTIF('Social Studies'!$A:$A,$A14) -> 10 | H14: =COUNTIF(Computer!$A:$A,$A14) -> 6 | I14: =SUM(B14:H14) -> 65
A15: 10 | B15: =COUNTIF(Mathematics!$A:$A,$A15) -> 10 | C15: =COUNTIF(English!$A:$A,$A15) -> 9 | D15: =COUNTIF(Hindi!$A:$A,$A15) -> 6 | E15: =COUNTIF('Science 1-8'!$A:$A,$A15) -> 0 | F15: =COUNTIF('PCB 9-12'!$A:$A,$A15) -> 25 | G15: =COUNTIF('Social Studies'!$A:$A,$A15) -> 10 | H15: =COUNTIF(Computer!$A:$A,$A15) -> 8 | I15: =SUM(B15:H15) -> 68
A16: 11 | B16: =COUNTIF(Mathematics!$A:$A,$A16) -> 10 | C16: =COUNTIF(English!$A:$A,$A16) -> 8 | D16: =COUNTIF(Hindi!$A:$A,$A16) -> 0 | E16: =COUNTIF('Science 1-8'!$A:$A,$A16) -> 0 | F16: =COUNTIF('PCB 9-12'!$A:$A,$A16) -> 26 | G16: =COUNTIF('Social Studies'!$A:$A,$A16) -> 0 | H16: =COUNTIF(Computer!$A:$A,$A16) -> 7 | I16: =SUM(B16:H16) -> 51
A17: 12 | B17: =COUNTIF(Mathematics!$A:$A,$A17) -> 10 | C17: =COUNTIF(English!$A:$A,$A17) -> 8 | D17: =COUNTIF(Hindi!$A:$A,$A17) -> 0 | E17: =COUNTIF('Science 1-8'!$A:$A,$A17) -> 0 | F17: =COUNTIF('PCB 9-12'!$A:$A,$A17) -> 26 | G17: =COUNTIF('Social Studies'!$A:$A,$A17) -> 0 | H17: =COUNTIF(Computer!$A:$A,$A17) -> 7 | I17: =SUM(B17:H17) -> 51
A18: Total | B18: =SUM(B6:B17) -> 103 | C18: =SUM(C6:C17) -> 92 | D18: =SUM(D6:D17) -> 63 | E18: =SUM(E6:E17) -> 63 | F18: =SUM(F6:F17) -> 101 | G18: =SUM(G6:G17) -> 80 | H18: =SUM(H6:H17) -> 74 | I18: =SUM(I6:I17) -> 576
A20: Estimated teaching hours
A21: Grade | B21: Mathematics | C21: English | D21: Hindi | E21: Science 1-8 | F21: PCB 9-12 | G21: Social Studies | H21: Computer | I21: Total
A22: 1 | B22: =SUMIF(Mathematics!$A:$A,$A22,Mathematics!$M:$M) -> 120 | C22: =SUMIF(English!$A:$A,$A22,English!$M:$M) -> 135 | D22: =SUMIF(Hindi!$A:$A,$A22,Hindi!$M:$M) -> 100 | E22: =SUMIF('Science 1-8'!$A:$A,$A22,'Science 1-8'!$M:$M) -> 51 | F22: =SUMIF('PCB 9-12'!$A:$A,$A22,'PCB 9-12'!$M:$M) -> 0 | G22: =SUMIF('Social Studies'!$A:$A,$A22,'Social Studies'!$M:$M) -> 50 | H22: =SUMIF(Computer!$A:$A,$A22,Computer!$M:$M) -> 54 | I22: =SUM(B22:H22) -> 510
A23: 2 | B23: =SUMIF(Mathematics!$A:$A,$A23,Mathematics!$M:$M) -> 122 | C23: =SUMIF(English!$A:$A,$A23,English!$M:$M) -> 138 | D23: =SUMIF(Hindi!$A:$A,$A23,Hindi!$M:$M) -> 100 | E23: =SUMIF('Science 1-8'!$A:$A,$A23,'Science 1-8'!$M:$M) -> 57 | F23: =SUMIF('PCB 9-12'!$A:$A,$A23,'PCB 9-12'!$M:$M) -> 0 | G23: =SUMIF('Social Studies'!$A:$A,$A23,'Social Studies'!$M:$M) -> 58 | H23: =SUMIF(Computer!$A:$A,$A23,Computer!$M:$M) -> 56 | I23: =SUM(B23:H23) -> 531
A24: 3 | B24: =SUMIF(Mathematics!$A:$A,$A24,Mathematics!$M:$M) -> 130 | C24: =SUMIF(English!$A:$A,$A24,English!$M:$M) -> 142 | D24: =SUMIF(Hindi!$A:$A,$A24,Hindi!$M:$M) -> 100 | E24: =SUMIF('Science 1-8'!$A:$A,$A24,'Science 1-8'!$M:$M) -> 85 | F24: =SUMIF('PCB 9-12'!$A:$A,$A24,'PCB 9-12'!$M:$M) -> 0 | G24: =SUMIF('Social Studies'!$A:$A,$A24,'Social Studies'!$M:$M) -> 75 | H24: =SUMIF(Computer!$A:$A,$A24,Computer!$M:$M) -> 60 | I24: =SUM(B24:H24) -> 592
A25: 4 | B25: =SUMIF(Mathematics!$A:$A,$A25,Mathematics!$M:$M) -> 126 | C25: =SUMIF(English!$A:$A,$A25,English!$M:$M) -> 142 | D25: =SUMIF(Hindi!$A:$A,$A25,Hindi!$M:$M) -> 100 | E25: =SUMIF('Science 1-8'!$A:$A,$A25,'Science 1-8'!$M:$M) -> 88 | F25: =SUMIF('PCB 9-12'!$A:$A,$A25,'PCB 9-12'!$M:$M) -> 0 | G25: =SUMIF('Social Studies'!$A:$A,$A25,'Social Studies'!$M:$M) -> 77 | H25: =SUMIF(Computer!$A:$A,$A25,Computer!$M:$M) -> 62 | I25: =SUM(B25:H25) -> 595
A26: 5 | B26: =SUMIF(Mathematics!$A:$A,$A26,Mathematics!$M:$M) -> 132 | C26: =SUMIF(English!$A:$A,$A26,English!$M:$M) -> 146 | D26: =SUMIF(Hindi!$A:$A,$A26,Hindi!$M:$M) -> 100 | E26: =SUMIF('Science 1-8'!$A:$A,$A26,'Science 1-8'!$M:$M) -> 90 | F26: =SUMIF('PCB 9-12'!$A:$A,$A26,'PCB 9-12'!$M:$M) -> 0 | G26: =SUMIF('Social Studies'!$A:$A,$A26,'Social Studies'!$M:$M) -> 81 | H26: =SUMIF(Computer!$A:$A,$A26,Computer!$M:$M) -> 64 | I26: =SUM(B26:H26) -> 613
A27: 6 | B27: =SUMIF(Mathematics!$A:$A,$A27,Mathematics!$M:$M) -> 138 | C27: =SUMIF(English!$A:$A,$A27,English!$M:$M) -> 146 | D27: =SUMIF(Hindi!$A:$A,$A27,Hindi!$M:$M) -> 100 | E27: =SUMIF('Science 1-8'!$A:$A,$A27,'Science 1-8'!$M:$M) -> 90 | F27: =SUMIF('PCB 9-12'!$A:$A,$A27,'PCB 9-12'!$M:$M) -> 0 | G27: =SUMIF('Social Studies'!$A:$A,$A27,'Social Studies'!$M:$M) -> 85 | H27: =SUMIF(Computer!$A:$A,$A27,Computer!$M:$M) -> 76 | I27: =SUM(B27:H27) -> 635
A28: 7 | B28: =SUMIF(Mathematics!$A:$A,$A28,Mathematics!$M:$M) -> 134 | C28: =SUMIF(English!$A:$A,$A28,English!$M:$M) -> 148 | D28: =SUMIF(Hindi!$A:$A,$A28,Hindi!$M:$M) -> 100 | E28: =SUMIF('Science 1-8'!$A:$A,$A28,'Science 1-8'!$M:$M) -> 92 | F28: =SUMIF('PCB 9-12'!$A:$A,$A28,'PCB 9-12'!$M:$M) -> 0 | G28: =SUMIF('Social Studies'!$A:$A,$A28,'Social Studies'!$M:$M) -> 84 | H28: =SUMIF(Computer!$A:$A,$A28,Computer!$M:$M) -> 78 | I28: =SUM(B28:H28) -> 636
A29: 8 | B29: =SUMIF(Mathematics!$A:$A,$A29,Mathematics!$M:$M) -> 138 | C29: =SUMIF(English!$A:$A,$A29,English!$M:$M) -> 150 | D29: =SUMIF(Hindi!$A:$A,$A29,Hindi!$M:$M) -> 100 | E29: =SUMIF('Science 1-8'!$A:$A,$A29,'Science 1-8'!$M:$M) -> 99 | F29: =SUMIF('PCB 9-12'!$A:$A,$A29,'PCB 9-12'!$M:$M) -> 0 | G29: =SUMIF('Social Studies'!$A:$A,$A29,'Social Studies'!$M:$M) -> 88 | H29: =SUMIF(Computer!$A:$A,$A29,Computer!$M:$M) -> 80 | I29: =SUM(B29:H29) -> 655
A30: 9 | B30: =SUMIF(Mathematics!$A:$A,$A30,Mathematics!$M:$M) -> 144 | C30: =SUMIF(English!$A:$A,$A30,English!$M:$M) -> 152 | D30: =SUMIF(Hindi!$A:$A,$A30,Hindi!$M:$M) -> 105 | E30: =SUMIF('Science 1-8'!$A:$A,$A30,'Science 1-8'!$M:$M) -> 0 | F30: =SUMIF('PCB 9-12'!$A:$A,$A30,'PCB 9-12'!$M:$M) -> 310 | G30: =SUMIF('Social Studies'!$A:$A,$A30,'Social Studies'!$M:$M) -> 89 | H30: =SUMIF(Computer!$A:$A,$A30,Computer!$M:$M) -> 82 | I30: =SUM(B30:H30) -> 882
A31: 10 | B31: =SUMIF(Mathematics!$A:$A,$A31,Mathematics!$M:$M) -> 144 | C31: =SUMIF(English!$A:$A,$A31,English!$M:$M) -> 154 | D31: =SUMIF(Hindi!$A:$A,$A31,Hindi!$M:$M) -> 105 | E31: =SUMIF('Science 1-8'!$A:$A,$A31,'Science 1-8'!$M:$M) -> 0 | F31: =SUMIF('PCB 9-12'!$A:$A,$A31,'PCB 9-12'!$M:$M) -> 312 | G31: =SUMIF('Social Studies'!$A:$A,$A31,'Social Studies'!$M:$M) -> 90 | H31: =SUMIF(Computer!$A:$A,$A31,Computer!$M:$M) -> 86 | I31: =SUM(B31:H31) -> 891
A32: 11 | B32: =SUMIF(Mathematics!$A:$A,$A32,Mathematics!$M:$M) -> 144 | C32: =SUMIF(English!$A:$A,$A32,English!$M:$M) -> 148 | D32: =SUMIF(Hindi!$A:$A,$A32,Hindi!$M:$M) -> 0 | E32: =SUMIF('Science 1-8'!$A:$A,$A32,'Science 1-8'!$M:$M) -> 0 | F32: =SUMIF('PCB 9-12'!$A:$A,$A32,'PCB 9-12'!$M:$M) -> 322 | G32: =SUMIF('Social Studies'!$A:$A,$A32,'Social Studies'!$M:$M) -> 0 | H32: =SUMIF(Computer!$A:$A,$A32,Computer!$M:$M) -> 86 | I32: =SUM(B32:H32) -> 700
A33: 12 | B33: =SUMIF(Mathematics!$A:$A,$A33,Mathematics!$M:$M) -> 146 | C33: =SUMIF(English!$A:$A,$A33,English!$M:$M) -> 152 | D33: =SUMIF(Hindi!$A:$A,$A33,Hindi!$M:$M) -> 0 | E33: =SUMIF('Science 1-8'!$A:$A,$A33,'Science 1-8'!$M:$M) -> 0 | F33: =SUMIF('PCB 9-12'!$A:$A,$A33,'PCB 9-12'!$M:$M) -> 324 | G33: =SUMIF('Social Studies'!$A:$A,$A33,'Social Studies'!$M:$M) -> 0 | H33: =SUMIF(Computer!$A:$A,$A33,Computer!$M:$M) -> 88 | I33: =SUM(B33:H33) -> 710
A34: Total | B34: =SUM(B22:B33) -> 1618 | C34: =SUM(C22:C33) -> 1753 | D34: =SUM(D22:D33) -> 1010 | E34: =SUM(E22:E33) -> 652 | F34: =SUM(F22:F33) -> 1268 | G34: =SUM(G22:G33) -> 777 | H34: =SUM(H22:H33) -> 872 | I34: =SUM(I22:I33) -> 7950
A36: Note: hours are planning estimates (see README). Grades 11-12 = ISC Science stream only in this draft. Science appears in 'Science 1-8' through Grade 8 and splits into 'PCB 9-12' from Grade 9; both cover the same strand.

Sheet Mathematics
A1: Grade | B1: Unit_No | C1: Unit | D1: Concept_Blocks | E1: Prerequisites | F1: Delivery | G1: Practice | H1: Mastery_Proof | I1: Unlocks | J1: Path_Lock | K1: Scholar_Depth | L1: Board_Ref | M1: Est_Hours
A2: 1 | B2: 1 | C2: Numbers to 20 | D2: Counting objects to 20 | One-to-one correspondence | Reading and writing numerals 0-20 | Comparing quantities (more/less/equal) | Ordinal numbers 1st-10th | Number bonds to 10 | E2: None | F2: M+T+O, low-screen; counters, ten-frames | G2: Concrete games + printed worksheets | H2: Oral count-and-show + written numeral check | I2: G1 U2 (Add/Sub within 20) | J2: Fluency: recognizes to 10 instantly | K2: Number-bond puzzles to 20; missing-number chains | L2: CISCE framework; school-defined (NCF-aligned) | M2: 24
A3: 1 | B3: 2 | C3: Addition and Subtraction within 20 | D3: Addition as combining | Subtraction as taking away | Number-line hops | Fact families | Doubles and near-doubles | Making-ten strategy | Simple story sums | E3: G1 U1 (Numbers to 20) | F3: M+T, low-screen; beads and ten-frames | G3: Daily 5-min fact drills + printed worksheets | H3: Oral story-sum solve + written check | I3: G1 U3 (Numbers to 100); G2 U2 | J3: Fluency: 15 facts/min within 10, no fingers | K3: Open sums: how many ways to make 12; dot-pattern proofs | L3: CISCE framework; school-defined (NCF-aligned) | M3: 24
A4: 1 | B4: 3 | C4: Numbers to 100 | D4: Counting in tens | Tens and ones (place value) | Reading and writing 2-digit numbers | Comparing and ordering to 100 | Skip counting in 2s/5s/10s | Patterns on the 100-grid | E4: G1 U1 (Numbers to 20) | F4: M+T, low-screen; bundles and 100-grid | G4: 100-grid games + printed worksheets | H4: Build-a-number with rods + written check | I4: G2 U1 (Numbers to 999) | J4: Place value: explains 34 as 3 tens 4 ones with materials | K4: 100-grid pattern hunts; two-step skip patterns | L4: CISCE framework; school-defined (NCF-aligned) | M4: 22
A5: 1 | B5: 4 | C5: Shapes, Patterns and Space | D5: 2D shapes: circle, triangle, square, rectangle | 3D solids: ball, box, cylinder, cone | Sorting by one attribute | Repeating patterns | Position words (above/below/left/right) | E5: None | F5: M+T+P, low-screen; shape hunts | G5: Sorting trays + pattern strips | H5: Shape sort + oral naming walk | I5: G2 U4 (Shapes and Lines) | J5: Naming: identifies shapes in any orientation | K5: Tangram builds; grow-a-pattern rules | L5: CISCE framework; school-defined (NCF-aligned) | M5: 18
A6: 1 | B6: 5 | C6: Measurement with Non-standard Units | D6: Comparing length (longer/shorter) | Comparing weight (heavier/lighter) | Comparing capacity (holds more/less) | Measuring with handspans and cubes | Why units must repeat with no gaps | E6: None | F6: M+T+P, low-screen; measuring stations | G6: Station task cards, estimate-then-measure | H6: Measure-and-record task + oral reasoning | I6: G2 U5 (Standard Units) | J6: Method: iterates units with no gaps or overlaps | K6: Estimation contests with personal benchmarks | L6: CISCE framework; school-defined (NCF-aligned) | M6: 16
A7: 1 | B7: 6 | C7: Time, Money and Picture Data | D7: Day/night and days of the week | O'clock on the analog clock | Recognising coins and notes | Making small amounts | Reading and making simple pictographs | E7: G1 U1 (Numbers to 20) | F7: M+T+O, low-screen; play money and clock | G7: Role-play shop + clock cards | H7: Clock-setting + coin-count task, oral | I7: G2 U6 (Time, Money and Data) | J7: Application: reads o'clock and counts mixed coins to Rs 20 | K7: Make-your-own pictograph survey | L7: CISCE framework; school-defined (NCF-aligned) | M7: 16
A8: 2 | B8: 1 | C8: Numbers to 999 | D8: Hundreds, tens and ones | Reading and writing 3-digit numbers | Expanded form | Comparing and ordering | Skip counting in 2s/3s/5s/10s | Number names to 999 | E8: G1 U3 (Numbers to 100) | F8: M+T, low-screen; place-value blocks | G8: Place-value mats + printed worksheets | H8: Build-expand-compare written check + oral explain | I8: G2 U2; G3 U1 (Numbers to 9,999) | J8: Place value: regroups 10 tens = 1 hundred with blocks | K8: Largest/smallest number puzzles with digit cards | L8: CISCE framework; school-defined (NCF-aligned) | M8: 22
A9: 2 | B9: 2 | C9: Addition and Subtraction with Regrouping | D9: 2-digit addition with carrying | 2-digit subtraction with borrowing | 3-digit add/sub with regrouping | Estimating by rounding to tens | Two-step story problems | Checking by the inverse operation | E9: G1 U2; G2 U1 | F9: M+T, low-screen; blocks fading to algorithm | G9: Practice ladder L1-L4 + daily drills | H9: Written check + regrouping explained with blocks | I9: G3 U2 (Add/Sub to 4 digits) | J9: Fluency: 20 facts/min to 20; algorithm works without blocks | K9: Missing-digit puzzles; magic squares | L9: CISCE framework; school-defined (NCF-aligned) | M9: 26
A10: 2 | B10: 3 | C10: Multiplication Foundations | D10: Equal groups | Repeated addition | Arrays (rows and columns) | Tables of 2, 5 and 10 | Tables of 3 and 4 | Division as equal sharing (readiness) | E10: G2 U2 | F10: M+T, low-screen; counters and arrays | G10: Skip-count chants + array cards + timed table drills | H10: Oral tables + array drawn for a story problem | I10: G3 U3 (Multiplication); G3 U4 (Division) | J10: Fluency: tables 2, 5, 10 instant recall | K10: Array factor hunts (all ways to make 12); doubling patterns | L10: CISCE framework; school-defined (NCF-aligned) | M10: 24
A11: 2 | B11: 4 | C11: Shapes, Lines and Patterns | D11: Straight and curved lines | 2D shape properties (sides, corners) | 3D solids (faces, edges, corners) | Symmetry by folding | Growing patterns | E11: G1 U4 (Shapes and Space) | F11: M+T+P, low-screen; fold-and-cut symmetry | G11: Geoboard tasks + pattern worksheets | H11: Shape-property sort + oral justification | I11: G3 U6 (Geometry and Measurement) | J11: Properties: counts sides/corners/faces correctly unaided | K11: Pentomino explorations; mirror-image drawing | L11: CISCE framework; school-defined (NCF-aligned) | M11: 16
A12: 2 | B12: 5 | C12: Measurement with Standard Units | D12: Centimetre and metre with a ruler | Kilogram with a balance | Litre with containers | Choosing a sensible unit | Estimate then measure | E12: G1 U5 (Non-standard Units) | F12: M+T+P, low-screen; measuring stations | G12: Station record sheets | H12: Measure 5 objects to nearest cm, written record | I12: G3 U6 (Geometry and Measurement) | J12: Accuracy: reads ruler from zero, within 0.5 cm | K12: Body-benchmark estimation olympiad | L12: CISCE framework; school-defined (NCF-aligned) | M12: 18
A13: 2 | B13: 6 | C13: Time, Money and Data | D13: Half past on the analog clock | Calendar: months and dates | Rupees and paise notation | Making amounts and giving change | Tally marks | Pictographs with a scale of 1 | E13: G1 U6 (Time, Money and Picture Data) | F13: M+T+O, low-screen; class shop project | G13: Role-play shop tasks + printed sheets | H13: Change-making task + clock read, oral | I13: G3 U7 (Time, Money and Data Handling) | J13: Application: gives correct change from Rs 100 | K13: Plan a class party budget within Rs 500 | L13: CISCE framework; school-defined (NCF-aligned) | M13: 16
... A104: 12 | B104: 10 | C104: Applications of Integrals | D104: Area under a curve | Sign care: area between curve and axis | Area between two curves | Standard regions: parabola, circle and line combinations | E104: G12 U5 | F104: A+T+R, board-format | G104: Practice ladder + PYQ sets | H104: Board-format: sketch + shaded region + evaluated integral | I104: ISC board readiness | J104: Rigor: sketch precedes setup; limits justified | K104: Volumes of revolution (beyond syllabus); numerical integration | L104: ISC XII Sec B: Application of Integrals | M104: 8

Sheet English
A1: Grade | B1: Unit_No | C1: Unit | D1: Concept_Blocks | E1: Prerequisites | F1: Delivery | G1: Practice | H1: Mastery_Proof | I1: Unlocks | J1: Path_Lock | K1: Scholar_Depth | L1: Board_Ref | M1: Est_Hours
A2: 1 | B2: 1 | C2: Oral language & listening foundations | D2: Listening to stories | Following 2-step instructions | Naming & describing objects | Turn-taking in conversation | Rhymes & chants | E2: None | F2: O+T+M | G2: Daily circle time; picture-talk cards; rhyme chanting | H2: Teacher-observed oral checklist: retells a heard story in 3+ sentences | I2: G1 U2 | J2: Follows 2-step oral instructions unaided | K2: Tells an original 5-sentence story to the class | L2: CISCE framework; school-defined (NCF-aligned) | M2: 26
A3: 1 | B3: 2 | C3: Phonics I: letter sounds & CVC blending | D3: Letter-sound correspondence | Oral blending & segmenting | CVC word decoding | Beginning & ending sounds | Alphabet formation | E3: G1 U1 (Oral language foundations) | F3: M+T | G3: Decodable readers + letter-tile blending drills | H3: One-to-one decoding check: reads 18/20 CVC words cold | I3: G1 U3 | J3: CVC decoding at 90%+ accuracy | K3: Reads decodable books one band above level | L3: CISCE framework; school-defined (NCF-aligned) | M3: 30
A4: 1 | B4: 3 | C4: Phonics II: digraphs, blends & sight words | D4: sh/ch/th digraphs | Consonant blends | First 100 sight words | Word families (-at/-an/-in) | Simple sentence reading | E4: G1 U2 (Phonics I) | F4: M+T | G4: Levelled readers + running records; sight-word flashcard cycles | H4: Running record on unseen levelled text at 90%+ accuracy | I4: G1 U4 | J4: Reads 80/100 sight words on sight | K4: Decodes two-syllable words | L4: CISCE framework; school-defined (NCF-aligned) | M4: 28
A5: 1 | B5: 4 | C5: Shared reading & first comprehension | D5: Picture-supported reading | Who/what/where questions | Retelling in sequence | Predicting what happens next | E5: G1 U3 (Phonics II) | F5: M+T+O | G5: Guided reading groups + oral retell prompts | H5: Oral retell of an unseen levelled story with beginning-middle-end | I5: G1 U5 | J5: Oral reading fluency >= 30 wcpm on level text | K5: Reads aloud to a younger buddy class | L5: CISCE framework; school-defined (NCF-aligned) | M5: 22
A6: 1 | B6: 5 | C6: First writing: letters to sentences | D6: Handwriting & spacing | Writing CVC and sight words | Capital letter + full stop | Writing one complete sentence | Labelling pictures | E6: G1 U2 (Phonics I) | F6: M+T | G6: Daily copywork moving to dictated-sentence writing | H6: Writes 3 dictated sentences unaided with capitals and full stops | I6: G1 U6 | J6: Writes an original sentence without copying | K6: Writes a 3-sentence picture story | L6: CISCE framework; school-defined (NCF-aligned) | M6: 16
A7: 1 | B7: 6 | C7: Word play: vocabulary, rhyme & performance | D7: Rhyming pairs | Opposites | Naming words vs doing words | Poem recitation | New words from stories | E7: G1 U1 (Oral language foundations) | F7: O+M+T | G7: Rhyme games + word wall + weekly recitation slot | H7: Recites an 8-line poem from memory; sorts 20 words by category | I7: G2 U1 | J7: Recitation from memory with audible clarity | K7: Performs a poem at school assembly | L7: CISCE framework; school-defined (NCF-aligned) | M7: 13
A8: 2 | B8: 1 | C8: Phonics III: long vowels & fluency | D8: Magic-e words | Vowel teams (ai/ee/oa) | r-controlled vowels | Two-syllable decoding | Fluency phrasing | E8: G1 U3 (Phonics II) | F8: M+T | G8: Decodable + levelled readers with running records | H8: Running record: unseen text at 95%+ accuracy | I8: G2 U2 | J8: Oral reading fluency >= 50 wcpm | K8: Maintains a chapter-book reading log | L8: CISCE framework; school-defined (NCF-aligned) | M8: 28
A9: 2 | B9: 2 | C9: Comprehension: retell, sequence & why-questions | D9: Story sequencing | Character & setting | Why/how questions | Retelling with details | Fact vs make-believe | E9: G2 U1 (Phonics III & fluency) | F9: M+T+O | G9: Guided reading groups + story maps | H9: Oral and written answers on an unseen story read independently | I9: G2 U3 | J9: Answers why-questions citing a story detail | K9: Retells a folk tale from another culture | L9: CISCE framework; school-defined (NCF-aligned) | M9: 24
A10: 2 | B10: 3 | C10: Grammar I: nouns, verbs & describing words | D10: Nouns (naming words) | Verbs (doing words) | Adjectives | Singular & plural | a/an/the | Capital letters for names | E10: G1 U5 (First writing) | F10: M+T | G10: Word-sorting games + sentence-building strips | H10: Written check: builds and corrects 10 sentences unaided | I10: G2 U4 | J10: Identifies noun/verb/adjective in unseen sentences | K10: Expands sentences with two describing words | L10: CISCE framework; school-defined (NCF-aligned) | M10: 22
A11: 2 | B11: 4 | C11: Writing: from sentence to mini-paragraph | D11: Joining ideas with and/but | Writing 3-5 related sentences | My-news recount writing | Simple story frames | E11: G2 U3 (Grammar I) | F11: M+T | G11: Daily journal + teacher writing conferences | H11: Unaided 5-sentence recount, legible and sequenced | I11: G2 U5 | J11: Original writing without copying or prompts | K11: Creates an illustrated mini-book | L11: CISCE framework; school-defined (NCF-aligned) | M11: 24
A12: 2 | B12: 5 | C12: Stories & poems: first literature | D12: Favourite-author study | Poems with patterns | Characters we remember | Talking about books | Beginning-middle-end in stories | E12: G2 U2 (Comprehension: retell & sequence) | F12: M+T+O | G12: Read-aloud discussion + class book talks | H12: Book talk: presents a story's characters and ending to the class | I12: G2 U6 | J12: Speaks for 1 minute about a book unaided | K12: Compares two stories orally | L12: CISCE framework; school-defined (NCF-aligned) | M12: 22
A13: 2 | B13: 6 | C13: Speaking & listening: show-and-tell to short talks | D13: Show-and-tell structure | Listening for details | Asking good questions | Polite conversation | Recitation II | E13: G1 U6 (Word play & performance) | F13: O+T+M | G13: Weekly talk slot + listening games | H13: 2-minute prepared talk with 3 facts; answers 2 audience questions | I13: G3 U1 | J13: Sustains a 2-minute talk with eye contact | K13: Hosts a class morning assembly | L13: CISCE framework; school-defined (NCF-aligned) | M13: 18
... A93: 12 | B93: 8 | C93: Mock cycle, seminar & viva | D93: Full Paper 1 & Paper 2 mocks | Time-allocation strategy | Weak-spot remediation | Literature viva | Project-work completion | E93: G12 U4 (Grammar & usage); G12 U7 (Poetry mastery) | F93: T+O+M | G93: Fortnightly invigilated mocks + viva rounds | H93: Two full board mocks at target grade plus 10-minute viva without notes | I93: ISC board examination (exit) | J93: Both papers completed in time at target grade | K93: Leads Grade 11 revision seminars | L93: ISC English (801) Papers 1 & 2: full board format; Project Work | M93: 30

Sheet Hindi
A1: Grade | B1: Unit_No | C1: Unit | D1: Concept_Blocks | E1: Prerequisites | F1: Delivery | G1: Practice | H1: Mastery_Proof | I1: Unlocks | J1: Path_Lock | K1: Scholar_Depth | L1: Board_Ref | M1: Est_Hours
A2: 1 | B2: 1 | C2: Varnamala: Swar (Vowels) | D2: Vowel recognition a to ah (swar अ–अः) | Vowel sounds and mouth shapes (uchcharan) | Tracing and writing swar | Swar-picture association (a se anaar) | E2: None | F2: M+T+O | G2: Sand/slate tracing; swar flashcards; sound bingo | H2: Oral swar recitation + written swar test (teacher-checked) | I2: G1 U2 (Vyanjan) | J2: Hard — decoding gate for all reading | K2: Swar calligraphy cards; swar songs performance | L2: CISCE framework; school-defined (NCF-aligned) | M2: 16
A3: 1 | B3: 2 | C3: Varnamala: Vyanjan (Consonants) | D3: Consonant recognition ka to gya (vyanjan क–ज्ञ) | Consonant sounds by varg (ka-varg to pa-varg) | Writing vyanjan with correct stroke order | Letter-picture association (ka se kamal) | Distinguishing similar letters (ब/व, घ/ध) | E3: G1 U1 (Swar) | F3: M+T+O | G3: Daily copywriting; letter hunt games; varg sorting | H3: Shruti-lekh (letter dictation) + oral letter naming | I3: G1 U3 (Matras I) | J3: Hard — decoding gate | K3: Clay/rangoli letter making; alphabet chart creation | L3: CISCE framework; school-defined (NCF-aligned) | M3: 20
A4: 1 | B4: 3 | C4: Matras I: aa/i/ee/u/oo | D4: Matra concept — vowel signs on consonants | Aa ki matra words (ा) | Chhoti-badi ee ki matra (ि/ी) | Chhota-bada oo ki matra (ु/ू) | Two-letter matra words reading | E4: G1 U2 (Vyanjan) | F4: M+T+O | G4: Matra wheels; word building with letter tiles; matra worksheets | H4: Read 20 matra words aloud + shruti-lekh of 10 words | I4: G1 U4 (First Words); G2 U1 (Matras II) | J4: Hard — gates word reading | K4: Matra word-family booklets (self-made) | L4: CISCE framework; school-defined (NCF-aligned) | M4: 18
A5: 1 | B5: 4 | C5: First Words and Picture Reading | D5: Two/three-letter words without matra (do-akshar shabd) | Simple matra words in context | Picture-word matching | Naming words around me (family, animals, fruits) | Word wall vocabulary (50 words) | E5: G1 U3 (Matras I) | F5: M+T+O | G5: Picture dictionaries; label-the-classroom; word ladders | H5: Oral reading of word list + picture-word match test | I5: G1 U6 (Sentence Readiness); G2 U3 (Reading Fluency) | J5: Soft — remediate alongside G2 U1 | K5: Make-your-own picture shabd-kosh | L5: CISCE framework; school-defined (NCF-aligned) | M5: 16
A6: 1 | B6: 5 | C6: Shravan-Vachan: Rhymes and Listening | D6: Bal-geet recitation with actions | Listening to short stories (kahani shravan) | Following two-step oral instructions | Self-introduction in Hindi (mera naam, mera parivar) | Responding to simple questions orally | E6: None | F6: O+T+M | G6: Daily rhyme circle; story time; show-and-tell in Hindi | H6: Recite 2 rhymes + answer oral questions on a heard story | I6: G2 U6 (Kavita and Kahani) | J6: Soft | K6: Rhyme performance at assembly; new rhyme with actions | L6: CISCE framework; school-defined (NCF-aligned) | M6: 16
A7: 1 | B7: 6 | C7: Writing Readiness and First Sentences | D7: Pattern writing and letter formation drills | Copying words and short phrases | Writing own name and family names | Completing simple sentences with word bank (yeh ___ hai) | E7: G1 U3 (Matras I) | F7: M+T | G7: Handwriting books; sentence copying; fill-the-word cards | H7: Copy 3 sentences neatly + write 5 words from dictation | I7: G2 U5 (Vakya Rachna) | J7: Soft | K7: Decorated name cards; word art | L7: CISCE framework; school-defined (NCF-aligned) | M7: 14
A8: 2 | B8: 1 | C8: Matras II and Barakhadi Completion | D8: Matras of e/ai/o/au (े/ै/ो/ौ) | Anusvar and anunasik (ं/ँ) | Visarg (ः) | Full barakhadi fluency | Reading mixed-matra words | E8: G1 U3 (Matras I) | F8: M+T+O | G8: Barakhadi chanting; matra sorting races; word building | H8: Shruti-lekh (20 mixed-matra words) + barakhadi oral test | I8: G2 U2 (Samyukt Akshar); G2 U3 (Reading Fluency) | J8: Hard — gates fluent decoding | K8: Barakhadi chart authoring; matra puzzles for peers | L8: CISCE framework; school-defined (NCF-aligned) | M8: 20
A9: 2 | B9: 2 | C9: Conjunct Consonants (Samyukt Akshar) | D9: Halant and joined letters concept | Common conjuncts (क्ष, त्र, ज्ञ, श्र) | R-forms (र् combinations: क्र, र्क) | Double letters (च्च, न्न, ल्ल) | Reading conjunct words | E9: G2 U1 (Matras II) | F9: M+T+O | G9: Conjunct flashcards; break-the-word games; copywriting | H9: Read 15 conjunct words aloud + shruti-lekh of 10 | I9: G3 U1 (Reading Comprehension) | J9: Hard — gates fluent reading | K9: Find conjuncts in storybooks; conjunct word collection | L9: CISCE framework; school-defined (NCF-aligned) | M9: 16
A10: 2 | B10: 3 | C10: Reading Fluency: Sentences and Short Texts | D10: Reading simple sentences aloud | Short paragraph reading (4-5 sentences) | Punctuation awareness while reading (poorn viram pause) | Reading with expression | Sight vocabulary (100 words) | E10: G2 U1 (Matras II); G1 U4 (First Words) | F10: M+T+O | G10: Paired reading; leveled readers; echo reading | H10: Oral reading of an unseen short passage (teacher rubric) | I10: G3 U1 (Reading Comprehension) | J10: Hard — fluency gate | K10: Read-aloud to Grade 1 buddies | L10: CISCE framework; school-defined (NCF-aligned) | M10: 18
A11: 2 | B11: 4 | C11: Vocabulary and Word Sense | D11: Opposites (vilom shabd — basic pairs) | One and many (ek-anek: ladka/ladke) | Naming words vs action words (intuitive sangya/kriya) | Days, months, numbers in Hindi | Word families and rhyming words | E11: G2 U1 (Matras II) | F11: M+T+O | G11: Word walls; opposite-match cards; oral word games | H11: Written vilom/ek-anek quiz + oral word usage | I11: G3 U2 (Sangya, Ling, Vachan) | J11: Soft | K11: Personal shabd-kosh notebook | L11: CISCE framework; school-defined (NCF-aligned) | M11: 14
A12: 2 | B12: 5 | C12: Vakya Rachna: First Writing | D12: Simple sentence construction (subject + verb) | Word order in Hindi sentences | Poorn viram (।) and prashn chinh (?) | Writing 3-4 sentences on a picture | Capitalization-free script conventions and neatness | E12: G1 U6 (Writing Readiness); G2 U1 (Matras II) | F12: M+T | G12: Picture-prompt sentences; jumbled-word ordering; daily one-line diary | H12: Write 5 correct sentences on a given picture (unaided) | I12: G3 U5 (Anuchchhed Lekhan) | J12: Soft | K12: Two-line picture stories | L12: CISCE framework; school-defined (NCF-aligned) | M12: 16
A13: 2 | B13: 6 | C13: Kavita and Kahani: First Literature | D13: Kavita recitation with rhythm (laya) | Listening and retelling short kahani | Naming characters (patra) in a story | Answering who/what questions orally (kaun/kya) | Moral of the story (seekh) discussion | E13: G1 U5 (Shravan-Vachan) | F13: O+T+M | G13: Story circle; picture sequencing of stories; recitation practice | H13: Recite 1 kavita + oral retell of a story with 3 events in order | I13: G3 U6 (Kahani aur Kavita) | J13: Soft | K13: Class kavita competition; puppet retelling | L13: CISCE framework; school-defined (NCF-aligned) | M13: 16
... A64: 10 | B64: 6 | C64: Board Readiness: Full Papers and Internal Assessment | D64: Full-length paper practice (80M, 3 hrs) | Question selection strategy in Section B (4 questions, 2 texts) | Internal assessment portfolio (language + literature assignments) | Error-log clearance and weak-topic loops | Pre-board analysis and final revision plan | E64: G10 U1 (Nibandh Mastery); G10 U3 (Section A Drill); G10 U4 (Sahitya Sagar Completion); G10 U5 (Second Text Completion) | F64: T+R | G64: Three full mocks; paper-wise error autopsy; targeted revision | H64: Two full board-format papers at 60%+ (teacher-marked) | I64: ICSE Hindi board exam | J64: Hard — final gate | K64: Predict-the-paper exercise with justification | L64: ICSE Hindi (Second Language, Group I): full paper — Section A 40M (nibandh ~250w, patra, apathit gadyansh ~250w, vyakaran) + Section B 40M (4 Qs from 2 prescribed texts) + 20M internal assessment | M64: 17

Sheet Science 1-8
A1: Grade | B1: Unit_No | C1: Unit | D1: Concept_Blocks | E1: Prerequisites | F1: Delivery | G1: Practice | H1: Mastery_Proof | I1: Unlocks | J1: Path_Lock | K1: Scholar_Depth | L1: Board_Ref | M1: Est_Hours
A2: 1 | B2: 1 | C2: My Body and Senses | D2: Five senses and their body parts | What each sense tells us | Keeping the body clean | Naming external body parts | E2: None | F2: M+N+T | G2: Sense-station rotation + picture journal | H2: Sort objects by sense used + oral naming | I2: G1 U2 (Plants Around Us) | J2: Must name the sense, not just point | K2: Sensory-hunt scrapbook of the campus | L2: CISCE framework; school-defined (NCF-aligned) | M2: 9
A3: 1 | B3: 2 | C3: Plants Around Us | D3: Trees, shrubs, grass, creepers | Plants give us food and shade | Plants are living and grow | Caring for a plant | E3: None | F3: N+M+T | G3: Grow-a-seed pot + observation journal | H3: Draw-and-label a plant + oral viva | I3: G1 U3 (Animals Around Us) | J3: Must show a plant needs water and light | K3: Class garden plot log over a month | L3: CISCE framework; school-defined (NCF-aligned) | M3: 9
A4: 1 | B4: 3 | C4: Animals Around Us | D4: Pets, farm and wild animals | What animals eat | Animal babies and sounds | Animals are living and move | E4: None | F4: N+M+T | G4: Animal-sorting cards + observation journal | H4: Sort animals by home/food + oral naming | I4: G1 U4 (Weather and Sky) | J4: Must group by a stated reason | K4: Neighbourhood animal-spotting chart | L4: CISCE framework; school-defined (NCF-aligned) | M4: 9
A5: 1 | B5: 4 | C5: Weather and Sky | D5: Sunny, rainy, cloudy, windy days | Day and night | The Sun, Moon and stars | Dressing for the weather | E5: None | F5: N+T+M | G5: Daily weather calendar + drawing | H5: Match weather to clothing/activity + oral | I5: G1 U5 (Water and Its Uses) | J5: Must link weather to a daily choice | K5: Two-week home weather diary | L5: CISCE framework; school-defined (NCF-aligned) | M5: 8
A6: 1 | B6: 5 | C6: Water and Its Uses | D6: Where we get water | Uses of water at home | Water is precious - saving water | Clean vs dirty water | E6: None | F6: M+N+T | G6: Water-use hunt + picture chart | H6: List three uses + explain one saving habit | I6: G1 U6 (Materials Around Me) | J6: Must state one way to save water | K6: Home water-saving pledge poster | L6: CISCE framework; school-defined (NCF-aligned) | M6: 8
A7: 1 | B7: 6 | C7: Materials Around Me | D7: Wood, metal, plastic, cloth, paper | Hard and soft, rough and smooth | What things are made of | Sorting by feel | E7: None | F7: M+N+T | G7: Touch-and-sort tray + drawing | H7: Sort materials by property + oral reason | I7: G2 U1 (Living and Non-Living) | J7: Must sort by one named property | K7: Texture-collage of five materials | L7: CISCE framework; school-defined (NCF-aligned) | M7: 8
A8: 2 | B8: 1 | C8: Living and Non-Living | D8: Things that grow, move, eat, breathe | Living needs: food, water, air | Non-living things | Once-living things | E8: G1 U6 (Materials Around Me) | F8: M+N+T | G8: Living/non-living sort + journal | H8: Sort objects with a stated reason + oral | I8: G2 U2 (Parts of a Plant) | J8: Must justify using a life feature | K8: Classroom census of living things | L8: CISCE framework; school-defined (NCF-aligned) | M8: 10
A9: 2 | B9: 2 | C9: Parts of a Plant | D9: Root, stem, leaf, flower, fruit | What each part does | Plants make their own food (idea) | Plants we eat: root, leaf, fruit | E9: G1 U2 (Plants Around Us) | F9: N+M+T | G9: Real-plant dissection + label sheet | H9: Draw-and-label a plant + name each job | I9: G2 U3 (Animal Homes and Food) | J9: Must match each part to its function | K9: Kitchen-vegetable plant-part sort | L9: CISCE framework; school-defined (NCF-aligned) | M9: 10
A10: 2 | B10: 3 | C10: Animal Homes and Food | D10: Homes: nest, burrow, den, water | Herbivore, carnivore, omnivore (simple) | Land, water and air animals | How animals move | E10: G1 U3 (Animals Around Us) | F10: N+M+T | G10: Habitat-match cards + journal | H10: Match animal to home and food + oral | I10: G2 U4 (Food We Eat) | J10: Must give a reason for the match | K10: Habitat diorama of one animal | L10: CISCE framework; school-defined (NCF-aligned) | M10: 10
A11: 2 | B11: 4 | C11: Food We Eat | D11: Food from plants and animals | Energy foods, body-building foods, protective foods | Healthy vs junk food | Cooking changes food | E11: G2 U2 (Parts of a Plant) | F11: M+N+T | G11: Food-group plate sort + journal | H11: Build a healthy plate + explain choices | I11: G2 U5 (Air Around Us) | J11: Must group foods by a stated purpose | K11: One-day family meal food-map | L11: CISCE framework; school-defined (NCF-aligned) | M11: 9
A12: 2 | B12: 5 | C12: Air Around Us | D12: Air is all around us | We breathe air; plants and animals need it | Moving air is wind | Air helps things move (kites, sails) | E12: None | F12: N+M+L | G12: Balloon and pinwheel play + journal | H12: Show air takes space + explain wind | I12: G2 U6 (Day, Night and Seasons) | J12: Must demonstrate air is real | K12: Pinwheel-in-wind investigation | L12: CISCE framework; school-defined (NCF-aligned) | M12: 9
A13: 2 | B13: 6 | C13: Day, Night and Seasons | D13: Sun gives day, Moon and stars at night | Spinning Earth makes day and night (idea) | Four seasons and their weather | Festivals and seasons | E13: G1 U4 (Weather and Sky) | F13: N+T+M | G13: Season-wheel craft + observation log | H13: Order the day + name seasons with signs | I13: G3 U1 (Plants: Parts and Functions) | J13: Must link a season to observable signs | K13: Seasonal-change photo journal | L13: CISCE framework; school-defined (NCF-aligned) | M13: 9
... A64: 8 | B64: 9 | C64: Physics: Electricity and magnetism (intro) | D64: Static and current electricity (intro) | Simple circuits: cell, wire, bulb, switch | Conductors and insulators | Magnets, poles and fields | Electromagnetism (intro) | E64: G7 U1 (Physics: Heat and temperature) | F64: A+T+L | G64: Circuit-build lab + practice ladder | H64: Build a working circuit + explain flow | I64: G9 Physics: Electricity & Magnetism (ICSE 9) | J64: Must explain current using a circuit | K64: NSEJS-style circuit problems | L64: CISCE framework; school-defined (NCF-aligned) | M64: 11

Sheet PCB 9-12
A1: Grade | B1: Unit_No | C1: Unit | D1: Concept_Blocks | E1: Prerequisites | F1: Delivery | G1: Practice | H1: Mastery_Proof | I1: Unlocks | J1: Path_Lock | K1: Scholar_Depth | L1: Board_Ref | M1: Est_Hours
A2: 9 | B2: 1 | C2: Physics: Measurements and Experimentation | D2: SI and derived units | Measurement of length, mass, time | Vernier calipers and screw gauge | Least count and significant figures | Simple pendulum and time period | E2: G8 Science (Measurement) | F2: A+T+L+R, board-format (lab-heavy) | G2: Instrument-reading drills + lab journal | H2: Practical demo (vernier/screw gauge) + written numericals | I2: G9 Phy U2 | J2: Correct instrument reading without assistance | K2: Error analysis + NSEJS-style estimation | L2: ICSE Cl.9 Physics U1 Measurements and Experimentation (CISCE 2026-27) | M2: 10
A3: 9 | B3: 2 | C3: Physics: Motion in One Dimension | D3: Scalars and vectors | Distance, displacement, speed, velocity | Acceleration | Equations of motion | Distance-time and velocity-time graphs | E3: G9 Phy U1 | F3: A+T+R, board-format | G3: Numericals ladder + graph plotting | H3: Numerical set + graph interpretation (written) | I3: G9 Phy U3 | J3: Numericals without formula sheet | K3: Graph-based reasoning, relative velocity problems | L3: ICSE Cl.9 Physics U2 Motion in One Dimension | M3: 14
A4: 9 | B4: 3 | C4: Physics: Laws of Motion | D4: Newton's three laws | Inertia and momentum | Force and equilibrium | Gravitation and Newton's law | Weight vs mass | Contact and non-contact forces | E4: G9 Phy U2 | F4: A+T+R, board-format | G4: Numericals ladder + concept Qs | H4: Numerical set + oral reasoning | I4: G9 Phy U4 | J4: Free-body reasoning explained aloud | K4: NSEJS mechanics problems | L4: ICSE Cl.9 Physics U3 Laws of Motion | M4: 14
A5: 9 | B5: 4 | C5: Physics: Fluids (Pressure and Buoyancy) | D5: Thrust and pressure | Pressure in fluids and atmospheric pressure | Buoyancy and upthrust | Archimedes' principle | Density and relative density | Floatation | E5: G9 Phy U3 | F5: A+T+L+R, board-format (lab-heavy) | G5: Lab journal (RD of solid/liquid) + numericals | H5: Practical demo (relative density) + written numericals | I5: G9 Phy U5 | J5: Practical record signed off | K5: Floatation edge-cases, hydrometer design | L5: ICSE Cl.9 Physics U4 Fluids (Pressure, Buoyancy, Upthrust) | M5: 12
A6: 9 | B6: 5 | C6: Physics: Heat and Energy | D6: Concepts of heat and temperature | Thermal expansion | Anomalous expansion of water | Energy flow and sources | Green house effect and global warming | E6: G8 Science (Heat) | F6: A+T+R, board-format | G6: Concept Qs + short numericals | H6: Board-format written + reasoning | I6: G9 Phy U6 | J6: Conceptual explanation required | K6: Energy-source policy reading + estimation | L6: ICSE Cl.9 Physics U5 Heat and Energy | M6: 12
A7: 9 | B7: 6 | C7: Physics: Light (Reflection) | D7: Reflection at plane surfaces | Laws of reflection | Spherical mirrors | Image formation and ray diagrams | Uses of concave and convex mirrors | E7: G8 Science (Light) | F7: A+T+L+R, board-format (lab-heavy) | G7: Ray-diagram drills + lab journal | H7: Practical (mirror image) + ray-diagram written | I7: G9 Phy U7 | J7: Ray diagrams drawn to scale unaided | K7: Mirror-formula derivations (extension) | L7: ICSE Cl.9 Physics U6 Light | M7: 14
A8: 9 | B8: 7 | C8: Physics: Sound | D8: Nature and propagation of sound | Reflection of sound and echo | Range of hearing and ultrasound | Vibrations - free, forced, resonance | Characteristics of sound | E8: G9 Phy U2 | F8: A+T+R, board-format | G8: Numericals (echo) + concept Qs | H8: Numerical set + oral reasoning | I8: G9 Phy U8 | J8: Echo numericals without formula sheet | K8: Resonance experiments, SONAR problems | L8: ICSE Cl.9 Physics U7 Sound | M8: 14
A9: 9 | B9: 8 | C9: Physics: Electricity and Magnetism | D9: Current, potential difference, resistance | Ohm's law and simple circuits | Electric cells and combinations | Magnetism - properties and field lines | Electromagnet and its uses | E9: G9 Phy U1 | F9: A+T+L+R, board-format (lab-heavy) | G9: Circuit drills + lab journal | H9: Practical (circuit build) + numerical set | I9: G10 Phy U1 | J9: Circuit numericals without formula sheet | K9: Kirchhoff-style extension, electromagnet design | L9: ICSE Cl.9 Physics U8 Electricity and Magnetism | M9: 14
A10: 9 | B10: 1 | C10: Chemistry: The Language of Chemistry | D10: Symbols, valency, formulae | Ionic radicals and their formulae | Chemical equations - writing and balancing | Information from a chemical equation | E10: G8 Science (Matter) | F10: A+T+R, board-format | G10: Equation-balancing drills | H10: Balancing set + naming (written) | I10: G9 Chem U2 | J10: Balance equations unaided | K10: Complex radical formulae, NSEC intro | L10: ICSE Cl.9 Chemistry U1 The Language of Chemistry (verify against current CISCE PDF) | M10: 14
A11: 9 | B11: 2 | C11: Chemistry: Chemical Changes and Reactions | D11: Physical vs chemical changes | Types of chemical reactions | Energy changes in reactions | Conditions for chemical change | E11: G9 Chem U1 | F11: A+T+L+R, board-format | G11: Lab journal (reaction types) + concept Qs | H11: Practical demo + written reasoning | I11: G9 Chem U3 | J11: Practical record signed off | K11: Thermochemistry preview | L11: ICSE Cl.9 Chemistry U2 Chemical Changes and Reactions (verify against current CISCE PDF) | M11: 12
A12: 9 | B12: 3 | C12: Chemistry: Water | D12: Water as a solvent | Solutions - types and solubility | Hydrated and anhydrous substances | Water of crystallisation | Hard and soft water | E12: G8 Science (Matter) | F12: A+T+L+R, board-format | G12: Solubility lab + concept Qs | H12: Practical + written | I12: G9 Chem U4 | J12: Conceptual explanation required | K12: Solubility-curve analysis | L12: ICSE Cl.9 Chemistry U3 Water (verify against current CISCE PDF) | M12: 10
A13: 9 | B13: 4 | C13: Chemistry: Atomic Structure and Chemical Bonding | D13: Structure of atom - Bohr model | Atomic number, mass number, isotopes | Electronic configuration (first 20) | Electrovalent and covalent bonding | Lewis structures | E13: G9 Chem U1 | F13: A+T+R, board-format | G13: Config + bonding-diagram drills | H13: Written + oral reasoning (bond type) | I13: G9 Chem U5 | J13: Mechanism-level explanation required | K13: Quantum-model preview, NSEC set | L13: ICSE Cl.9 Chemistry U4 Atomic Structure and Chemical Bonding (verify against current CISCE PDF) | M13: 16
... A102: 12 | B102: 8 | C102: Biology: Ecology and Environment | D102: Organisms and populations | Ecosystem - structure and function | Energy flow and food chains | Nutrient cycling | Biodiversity and conservation | Environmental issues | E102: G10 Bio U8 | F102: A+T+P, board-format | G102: Field study + ecology project | H102: Written + project defence | I102: None (terminal) | J102: Ecosystem-analysis reasoning explained | K102: INBO ecology set + field research | L102: ISC Cl.12 Biology U5 Ecology and Environment | M102: 16

Sheet Social Studies
A1: Grade | B1: Unit_No | C1: Unit | D1: Concept_Blocks | E1: Prerequisites | F1: Delivery | G1: Practice | H1: Mastery_Proof | I1: Unlocks | J1: Path_Lock | K1: Scholar_Depth | L1: Board_Ref | M1: Est_Hours
A2: 1 | B2: 1 | C2: My Family and Me | D2: Who is in my family | Roles and care in the family | Elders and their stories | Families change and grow | E2: None | F2: T+P | G2: Family tree drawing and show-and-tell | H2: Introduce family orally and name each member's role | I2: G1-U2 | J2: Speaks about own family in own words, not memorized lines | K2: Interview a grandparent and retell one story | L2: CISCE framework; school-defined (NCF-aligned) | M2: 10
A3: 1 | B3: 2 | C3: My Home | D3: Kinds of homes | Rooms and what happens in them | Keeping home clean and safe | Who does what at home | E3: G1-U1 | F3: T+P | G3: Home corner role-play and chore sorting | H3: Describe own home and one way to help at home, orally | I3: G1-U3 | J3: Names real chores done at home, not picture-card matching | K3: Build a model home from waste material | L3: CISCE framework; school-defined (NCF-aligned) | M3: 10
A4: 1 | B4: 3 | C4: My School | D4: People in my school | My classroom and my day | School rules and why we have them | Playing and sharing | E4: G1-U2 | F4: T+P+O | G4: Classroom jobs chart and rule role-play | H4: Explain two school rules and why they matter, orally | I4: G1-U4 | J4: Gives a reason for each rule, not just the rule | K4: Make a picture guide of the school for a new student | L4: CISCE framework; school-defined (NCF-aligned) | M4: 10
A5: 1 | B5: 4 | C5: My Neighbourhood | D5: Places near my home | Neighbourhood helpers | Roads and staying safe | Being a good neighbour | E5: G1-U3 | F5: M+T+P | G5: Neighbourhood walk and picture-mapping | H5: Name five neighbourhood places and the helper at each, orally | I5: G1-U5 | J5: Real places from own neighbourhood, not the textbook town | K5: Thank-you card project for one local helper | L5: CISCE framework; school-defined (NCF-aligned) | M5: 10
A6: 1 | B6: 5 | C6: Festivals and Celebrations We Share | D6: Festivals in my family | Festivals of my friends | Food, clothes and songs | Respecting different celebrations | E6: G1-U4 | F6: T+P+O | G6: Festival show-and-tell calendar | H6: Describe one festival of own family and one of a friend's family, orally | I6: G2-U1 | J6: Talks about a festival not their own with accuracy and respect | K6: Class festival scrapbook page with captions | L6: CISCE framework; school-defined (NCF-aligned) | M6: 10
A7: 2 | B7: 1 | C7: Families Near and Far | D7: Kinds of families | My family tree | How families change | Caring across generations | E7: G1-U1 | F7: T+P | G7: Three-generation family tree project | H7: Present family tree and explain the relations orally | I7: G2-U2 | J7: Explains relations between people, not just names | K7: Family migration story - where did we come from | L7: CISCE framework; school-defined (NCF-aligned) | M7: 10
A8: 2 | B8: 2 | C8: Community Helpers and Work | D8: Jobs people do around us | Tools of each trade | Why every job matters | Work at home counts too | E8: G1-U4 | F8: T+P+O | G8: Helper-tool matching and role-play | H8: Match ten helpers to their work and describe one helper's day, orally | I8: G2-U3 | J8: Explains why a job matters; no job ranked as small | K8: Interview one worker in school and present findings | L8: CISCE framework; school-defined (NCF-aligned) | M8: 10
A9: 2 | B9: 3 | C9: Places in Our Neighbourhood | D9: Market, post office, clinic, park | What each place is for | Picture maps of my street | Finding my way | E9: G2-U2; G1-U4 | F9: M+T+P | G9: Draw a picture map from home to school | H9: Read a simple picture map and point the way between two places | I9: G2-U4 | J9: Uses the map to navigate, not memory of the drawing | K9: Add symbols and a key to the street map | L9: CISCE framework; school-defined (NCF-aligned) | M9: 10
A10: 2 | B10: 4 | C10: Rules, Safety and Getting Along | D10: Rules at home and school | Road safety signs | Taking turns and fairness | Solving quarrels with words | E10: G1-U3 | F10: T+O+P | G10: Traffic-sign games and fairness role-play | H10: Explain three safety rules and act out a fair solution to a quarrel | I10: G2-U5 | J10: Applies fairness to a new, unseen situation | K10: Design a safety poster for the school gate | L10: CISCE framework; school-defined (NCF-aligned) | M10: 10
A11: 2 | B11: 5 | C11: Village, Town and City | D11: Life in a village | Life in a town or city | Same needs, different places | Moving between them | E11: G2-U3 | F11: T+M+P | G11: Sort pictures village vs city and explain the sort | H11: Compare village and city life orally - two differences, one similarity | I11: G2-U6 | J11: Comparison uses needs (water, food, work), not just pictures | K11: Photo story of a family member's native place | L11: CISCE framework; school-defined (NCF-aligned) | M11: 9
A12: 2 | B12: 6 | C12: One India, Many Ways of Living | D12: Foods across India | Clothes and weather | Festivals across regions | Many languages, one country | E12: G2-U5; G1-U5 | F12: T+P+M | G12: India picture wall - food, dress, festival by region | H12: Show three regions on an India picture-map and tell one thing about each, orally | I12: G3-U1 | J12: Links food and clothes to place and weather, not costume stereotypes | K12: Cook-and-tell - one dish's journey across India | L12: CISCE framework; school-defined (NCF-aligned) | M12: 9
A13: 3 | B13: 1 | C13: Our Local Community | D13: My village, town or city and its landmarks | People and occupations around us | How the community meets daily needs | Local stories and place names | E13: G2-U5 | F13: T+P+M | G13: Local landmark walk and community web chart | H13: Present a talk on own locality - three landmarks, three occupations | I13: G3-U2 | J13: Content drawn from own locality, not the textbook town | K13: Local history fieldwork - oldest building or shop, with photos and report | L13: CISCE framework; school-defined (NCF-aligned) | M13: 11
... A81: 10 | B81: 10 | C81: Geography: India - Minerals, Agriculture, Industries, Transport and Waste | D81: Mineral and energy resources | Agriculture - major crops and farming systems | Agro-based and mineral-based industries | Transport - roadways, railways, airways, waterways | Waste management - impact and safe disposal | E81: G10-U9 | F81: M+T+A | G81: Crop and industry map practice + board-pattern questions | H81: Board-format structured answers + full-syllabus map test | I81: ICSE HCG board examination | J81: Location logic argued; full map command without atlas | K81: Ward waste-management audit with recommendations | L81: ICSE Class X HCG Paper 2 (Geography) - Mineral and Energy Resources; Agriculture; Manufacturing Industries; Transport; Waste Management | M81: 10

Sheet Computer
A1: Grade | B1: Unit_No | C1: Unit | D1: Concept_Blocks | E1: Prerequisites | F1: Delivery | G1: Practice | H1: Mastery_Proof | I1: Unlocks | J1: Path_Lock | K1: Scholar_Depth | L1: Board_Ref | M1: Est_Hours
A2: 1 | B2: 1 | C2: Machines Around Us | D2: What is a machine vs a living thing | Computers we see every day | Parts of a computer (picture cards) | People give instructions, machines follow | E2: None | F2: U+T | G2: Picture-card sorting and matching games | H2: Sort machine/not-machine cards and name computer parts aloud to teacher | I2: G1U2 | J2: Oral naming to teacher; no screen used | K2: Take-apart table: label parts of an old keyboard and mouse | L2: CISCE framework; school-defined (NCF-aligned) | M2: 12
A3: 1 | B3: 2 | C3: Giving Exact Instructions | D3: Sequencing without a computer | Human-robot game | One step at a time | Order matters | E3: G1U1 | F3: U+T | G3: Human-robot and treasure-hunt games | H3: Direct a partner through a 5-step course using exact spoken steps | I3: G1U3 | J3: Instructions spoken and drawn by child alone | K3: Design a new instruction game for the class | L3: CISCE framework; school-defined (NCF-aligned) | M3: 11
A4: 1 | B4: 3 | C4: Patterns and Sorting | D4: Repeating patterns in daily life | Sorting by colour, size, shape | Spot the odd one out | Predict what comes next | E4: G1U2 | F4: U+T | G4: Bead, block and card pattern puzzles | H4: Build and extend a 3-rule pattern and explain the rule | I4: G1U4 | J4: Explain the rule in own words | K4: Create a pattern hunt around the school | L4: CISCE framework; school-defined (NCF-aligned) | M4: 11
A5: 1 | B5: 4 | C5: Steps in Everyday Jobs | D5: A recipe is an algorithm | Morning-routine steps | Debugging a recipe | Missing-step detective | E5: G1U3 | F5: U+T | G5: Picture-sequencing and fix-the-recipe puzzles | H5: Arrange a jumbled 6-step picture story and spot the wrong step | I5: G1U5 | J5: Debug done solo on paper cards | K5: Write an 8-step recipe card for the family | L5: CISCE framework; school-defined (NCF-aligned) | M5: 10
A6: 1 | B6: 5 | C6: Screens, Devices and Care | D6: Gentle hands with devices | Screen time has limits | Ask an adult first | Eyes and posture rules | E6: None | F6: U+T | G6: Role-play and classroom device-care drills | H6: Demonstrate correct device handling and recite the ask-an-adult rule | I6: G2U1 | J6: Demonstrated live to teacher | K6: Make a device-care poster for a younger class | L6: CISCE framework; school-defined (NCF-aligned) | M6: 10
A7: 2 | B7: 1 | C7: Computers Hide Everywhere | D7: Input like senses, output like actions | Computers inside ATMs, washing machines, cars | What a computer cannot do | Humans decide, machines repeat | E7: G1U5 | F7: U+T | G7: Spot-the-computer scavenger-hunt worksheets | H7: Label input and output on 5 everyday machines and explain one aloud | I7: G2U2 | J7: Oral explanation required | K7: Interview an adult about a machine they use at work | L7: CISCE framework; school-defined (NCF-aligned) | M7: 12
A8: 2 | B8: 2 | C8: Maps, Arrows and Robots | D8: Grid maps and arrow codes | Turning left and right | Writing a path as symbols | Testing and fixing a path | E8: G1U2 | F8: U+T | G8: Floor-grid robot games and arrow-code worksheets | H8: Write an arrow code that walks a partner across a grid obstacle course | I8: G2U3 | J8: Child writes the code card unaided | K8: Design a maze and its solution code for classmates | L8: CISCE framework; school-defined (NCF-aligned) | M8: 12
